{
  "comments": [
    {
      "key": {
        "uuid": "9aa7fdbe_f8c32036",
        "filename": "sanity-check.py",
        "patchSetId": 4
      },
      "lineNbr": 26,
      "author": {
        "id": 113
      },
      "writtenOn": "2017-06-06T08:01:52Z",
      "side": 1,
      "message": "Note to self: we need to remove these exceptions after merging the patch",
      "range": {
        "startLine": 26,
        "startChar": 15,
        "endLine": 26,
        "endChar": 16
      },
      "revId": "e89131ba5c44e891f912315a8489df2e4bd46133",
      "serverId": "270e2033-b340-4cff-9539-693957ebf0e7",
      "unresolved": false
    }
  ]
}